<?xml version="1.0" encoding="utf-8"?>
<!-- This URDF was automatically created by SolidWorks to URDF Exporter! Originally created by Stephen Brawner (brawner@gmail.com) -->
    <!-- For more information, please see http://wiki.ros.org/sw_urdf_exporter -->
<robot
  name="brum_description">
  <link name="base_link"/>
  <joint name="base_frame_joint" type="fixed">
    <parent link="base_link"/>
    <child link="frame_link"/>
  </joint>
  <link
    name="frame_link">
    <inertial>
      <origin
        xyz="0.0584615327877124 0.0495736241849834 0.00795392985129649"
        rpy="0 0 0" />
      <mass
        value="0.26203100747214" />
      <inertia
        ixx="9.47884593300043E-05"
        ixy="1.00362258451212E-07"
        ixz="-2.70612383223972E-06"
        iyy="0.000270018591622297"
        iyz="5.22139160504474E-09"
        izz="0.00034733631299585" />
    </inertial>
    <visual>
      <origin
        xyz="0 0 0"
        rpy="0 0 0" />
      <geometry>
        <mesh
          filename="package://brum_description/meshes/frame_link.STL" />
      </geometry>
      <material
        name="">
        <color
          rgba="0.792156862745098 0.819607843137255 0.933333333333333 1" />
      </material>
    </visual>
    <collision>
      <origin
        xyz="0 0 0"
        rpy="0 0 0" />
      <geometry>
        <mesh
          filename="package://brum_description/meshes/frame_link.STL" />
      </geometry>
    </collision>
  </link>
  <link
    name="powerbank_link">
    <inertial>
      <origin
        xyz="-6.9389E-18 -0.013 -6.9389E-18"
        rpy="0 0 0" />
      <mass
        value="0.13192" />
      <inertia
        ixx="3.6752E-05"
        ixy="-1.034E-21"
        ixz="-6.8242E-21"
        iyy="0.00013386"
        iyz="1.2925E-23"
        izz="0.00011182" />
    </inertial>
    <visual>
      <origin
        xyz="0 0 0"
        rpy="0 0 0" />
      <geometry>
        <mesh
          filename="package://brum_description/meshes/powerbank_link.STL" />
      </geometry>
      <material
        name="">
        <color
          rgba="0.29804 0.29804 0.29804 1" />
      </material>
    </visual>
    <collision>
      <origin
        xyz="0 0 0"
        rpy="0 0 0" />
      <geometry>
        <mesh
          filename="package://brum_description/meshes/powerbank_link.STL" />
      </geometry>
    </collision>
  </link>
  <joint
    name="powerbank_joint"
    type="fixed">
    <origin
      xyz="0.016919 0.0505 -0.029"
      rpy="-1.5708 0 -1.5708" />
    <parent
      link="frame_link" />
    <child
      link="powerbank_link" />
    <axis
      xyz="0 0 0" />
  </joint>
  <link
    name="right_wheel">
    <inertial>
      <origin
        xyz="-1.8593E-08 -1.3155E-09 -0.011873"
        rpy="0 0 0" />
      <mass
        value="0.16695" />
      <inertia
        ixx="6.7296E-05"
        ixy="5.9539E-12"
        ixz="3.2304E-12"
        iyy="6.7293E-05"
        iyz="2.4005E-13"
        izz="0.00011321" />
    </inertial>
    <visual>
      <origin
        xyz="0 0 0"
        rpy="0 0 0" />
      <geometry>
        <mesh
          filename="package://brum_description/meshes/right_wheel.STL" />
      </geometry>
      <material
        name="wheel_material">
        <color
          rgba="0.79216 0.81961 0.93333 1" />
      </material>
    </visual>
    <collision>
      <origin
        xyz="0 0 0"
        rpy="0 0 0" />
      <geometry>
        <mesh
          filename="package://brum_description/meshes/right_wheel.STL" />
      </geometry>
    </collision>
  </link>
  <joint
    name="right_wheel_joint"
    type="continuous">
    <origin
      xyz="0.1098 -0.02875 -0.01815"
      rpy="1.5708 0 0" />
    <parent
      link="frame_link" />
    <child
      link="right_wheel" />
    <axis
      xyz="0 0 1" />
  </joint>
  <link
    name="left_wheel">
    <inertial>
      <origin
        xyz="-1.8593E-08 -1.3155E-09 -0.011873"
        rpy="0 0 0" />
      <mass
        value="0.16695" />
      <inertia
        ixx="6.7296E-05"
        ixy="5.9539E-12"
        ixz="3.2303E-12"
        iyy="6.7293E-05"
        iyz="2.4005E-13"
        izz="0.00011321" />
    </inertial>
    <visual>
      <origin
        xyz="0 0 0"
        rpy="0 0 0" />
      <geometry>
        <mesh
          filename="package://brum_description/meshes/left_wheel.STL" />
      </geometry>
      <material
        name="wheel_material">
        <color
          rgba="0.79216 0.81961 0.93333 1" />
      </material>
    </visual>
    <collision>
      <origin
        xyz="0 0 0"
        rpy="0 0 0" />
      <geometry>
        <mesh
          filename="package://brum_description/meshes/left_wheel.STL" />
      </geometry>
    </collision>
  </link>
  <joint
    name="left_wheel_joint"
    type="continuous">
    <origin
      xyz="0.1098 0.12975 -0.01815"
      rpy="-1.5708 0 0" />
    <parent
      link="frame_link" />
    <child
      link="left_wheel" />
    <axis
      xyz="0 0 -1" />
  </joint>
  <link
    name="camera_mount_link">
    <inertial>
      <origin
        xyz="0.021441 -0.01339 -0.0052887"
        rpy="0 0 0" />
      <mass
        value="0.0099197" />
      <inertia
        ixx="9.6418E-07"
        ixy="3.9818E-07"
        ixz="1.3937E-07"
        iyy="2.1227E-06"
        iyz="-8.2985E-08"
        izz="2.9255E-06" />
    </inertial>
    <visual>
      <origin
        xyz="0 0 0"
        rpy="0 0 0" />
      <geometry>
        <mesh
          filename="package://brum_description/meshes/camera_mount_link.STL" />
      </geometry>
      <material
        name="">
        <color
          rgba="0.77647 0.75686 0.73725 1" />
      </material>
    </visual>
    <collision>
      <origin
        xyz="0 0 0"
        rpy="0 0 0" />
      <geometry>
        <mesh
          filename="package://brum_description/meshes/camera_mount_link.STL" />
      </geometry>
    </collision>
  </link>
  <joint
    name="camera_mount_joint"
    type="fixed">
    <origin
      xyz="0.163248855994184 0.0767499999979599 0.0349999999999995"
      rpy="1.5707963267949 0 -1.5707963267949" />
    <parent
      link="frame_link" />
    <child
      link="camera_mount_link" />
    <axis
      xyz="0 0 0" />
  </joint>
  <link
    name="camera_link">
    <inertial>
      <origin
        xyz="1.4318E-12 -0.0056758 1.4404E-13"
        rpy="0 0 0" />
      <mass
        value="0.012179" />
      <inertia
        ixx="1.0523E-06"
        ixy="5.7936E-21"
        ixz="-9.7186E-13"
        iyy="2.1867E-06"
        iyz="-3.6328E-22"
        izz="1.4643E-06" />
    </inertial>
    <visual>
      <origin
        xyz="0 0 0"
        rpy="0 0 0" />
      <geometry>
        <mesh
          filename="package://brum_description/meshes/camera_link.STL" />
      </geometry>
      <material
        name="">
        <color
          rgba="0.10196 0.10196 0.10196 1" />
      </material>
    </visual>
    <collision>
      <origin
        xyz="0 0 0"
        rpy="0 0 0" />
      <geometry>
        <mesh
          filename="package://brum_description/meshes/camera_link.STL" />
      </geometry>
    </collision>
  </link>
  <joint
    name="camera_joint"
    type="fixed">
    <origin
      xyz="0.02625 -0.01777 -0.00875"
      rpy="1.5708 0 0" />
    <parent
      link="camera_mount_link" />
    <child
      link="camera_link" />
    <axis
      xyz="0 0 0" />
  </joint>
  <link
    name="under_cairrage_link">
    <inertial>
      <origin
        xyz="0.0375 0.0055345 -0.015987"
        rpy="0 0 0" />
      <mass
        value="0.014205" />
      <inertia
        ixx="1.8823E-06"
        ixy="-1.0574E-16"
        ixz="-5.3685E-16"
        iyy="8.7571E-06"
        iyz="-6.6875E-14"
        izz="7.595E-06" />
    </inertial>
    <visual>
      <origin
        xyz="0 0 0"
        rpy="0 0 0" />
      <geometry>
        <mesh
          filename="package://brum_description/meshes/under_cairrage_link.STL" />
      </geometry>
      <material
        name="">
        <color
          rgba="0.79216 0.81961 0.93333 1" />
      </material>
    </visual>
    <collision>
      <origin
        xyz="0 0 0"
        rpy="0 0 0" />
      <geometry>
        <mesh
          filename="package://brum_description/meshes/under_cairrage_link.STL" />
      </geometry>
    </collision>
  </link>
  <joint
    name="under_cairrage_joint"
    type="fixed">
    <origin
      xyz="0.1582 0.013 -0.02385"
      rpy="1.5708 0 1.5708" />
    <parent
      link="frame_link" />
    <child
      link="under_cairrage_link" />
    <axis
      xyz="0 0 0" />
  </joint>
  <link
    name="center_sonar_link">
    <inertial>
      <origin
        xyz="-0.00016398 -0.00016123 -0.0014079"
        rpy="0 0 0" />
      <mass
        value="0.0092238" />
      <inertia
        ixx="4.451E-07"
        ixy="5.3122E-10"
        ixz="9.1E-15"
        iyy="1.9394E-06"
        iyz="-3.5248E-09"
        izz="2.2647E-06" />
    </inertial>
    <visual>
      <origin
        xyz="0 0 0"
        rpy="0 0 0" />
      <geometry>
        <mesh
          filename="package://brum_description/meshes/center_sonar_link.STL" />
      </geometry>
      <material
        name="">
        <color
          rgba="0.79216 0.81961 0.93333 1" />
      </material>
    </visual>
    <collision>
      <origin
        xyz="0 0 0"
        rpy="0 0 0" />
      <geometry>
        <mesh
          filename="package://brum_description/meshes/center_sonar_link.STL" />
      </geometry>
    </collision>
  </link>
  <joint
    name="center_sonar_joint"
    type="fixed">
    <origin
      xyz="0.0377 0.0135 0.00675"
      rpy="0 0 0" />
    <parent
      link="under_cairrage_link" />
    <child
      link="center_sonar_link" />
    <axis
      xyz="0 0 0" />
  </joint>
  <link
    name="caster_link">
    <inertial>
      <origin
        xyz="0 0 0"
        rpy="0 0 0" />
      <mass
        value="0" />
      <inertia
        ixx="0"
        ixy="0"
        ixz="0"
        iyy="0"
        iyz="0"
        izz="0" />
    </inertial>
    <visual>
      <origin
        xyz="0 0 0"
        rpy="0 0 0" />
      <geometry>
        <mesh
          filename="package://brum_description/meshes/caster_link.STL" />
      </geometry>
      <material
        name="">
        <color
          rgba="1 1 1 1" />
      </material>
    </visual>
    <collision>
      <origin
        xyz="0 0 0"
        rpy="0 0 0" />
      <geometry>
        <mesh
          filename="package://brum_description/meshes/caster_link.STL" />
      </geometry>
    </collision>
  </link>
  <joint
    name="caster_joint"
    type="fixed">
    <origin
      xyz="-0.018201 0.0505 -0.0442"
      rpy="-1.5708 0 -1.5708" />
    <parent
      link="frame_link" />
    <child
      link="caster_link" />
    <axis
      xyz="0 0 0" />
  </joint>
</robot>