<?xml version="1.0" encoding="utf-8"?>
<!-- This URDF was automatically created by SolidWorks to URDF Exporter! Originally created by Stephen Brawner (brawner@gmail.com) 
     Commit Version: 1.6.0-4-g7f85cfe  Build Version: 1.6.7995.38578
     For more information, please see http://wiki.ros.org/sw_urdf_exporter -->
<robot name="brum">
  <link name="base_link"/>
  <joint name="base_frame_joint" type="fixed">
    <parent link="base_link"/>
    <child link="frame_link"/>
  </joint>
  <link
    name="frame_link">
    <inertial>
      <origin
        xyz="-0.051432 -0.00091594 0.0079105"
        rpy="0 0 0" />
      <mass
        value="0.26172" />
      <inertia
        ixx="9.478E-05"
        ixy="1.0036E-07"
        ixz="-2.7061E-06"
        iyy="0.00027002"
        iyz="5.2214E-09"
        izz="0.00034733" />
    </inertial>
    <visual>
      <origin
        xyz="0 0 0"
        rpy="0 0 0" />
      <geometry>
        <mesh
          filename="package://brum_description/meshes/frame_link.STL" />
      </geometry>
      <material
        name="">
        <color
          rgba="0.79216 0.81961 0.93333 1" />
      </material>
    </visual>
    <collision>
      <origin
        xyz="0 0 0"
        rpy="0 0 0" />
      <geometry>
        <mesh
          filename="package://brum_description/meshes/frame_link.STL" />
      </geometry>
    </collision>
  </link>
  <link
    name="powerbank_link">
    <inertial>
      <origin
        xyz="-6.9389E-18 -0.013 -6.9389E-18"
        rpy="0 0 0" />
      <mass
        value="0.13192" />
      <inertia
        ixx="3.6752E-05"
        ixy="-1.034E-21"
        ixz="-7.2895E-21"
        iyy="0.00013386"
        iyz="-2.068E-22"
        izz="0.00011182" />
    </inertial>
    <visual>
      <origin
        xyz="0 0 0"
        rpy="0 0 0" />
      <geometry>
        <mesh
          filename="package://brum_description/meshes/powerbank_link.STL" />
      </geometry>
      <material
        name="">
        <color
          rgba="0.29804 0.29804 0.29804 1" />
      </material>
    </visual>
    <collision>
      <origin
        xyz="0 0 0"
        rpy="0 0 0" />
      <geometry>
        <mesh
          filename="package://brum_description/meshes/powerbank_link.STL" />
      </geometry>
    </collision>
  </link>
  <joint
    name="powerbank_joint"
    type="fixed">
    <origin
      xyz="-0.092881 0 -0.029"
      rpy="-1.5708 0 -1.5708" />
    <parent
      link="frame_link" />
    <child
      link="powerbank_link" />
    <axis
      xyz="0 0 0" />
  </joint>
  <link
    name="right_wheel">
    <inertial>
      <origin
        xyz="-1.8593E-08 -1.3155E-09 -0.011873"
        rpy="0 0 0" />
      <mass
        value="0.16695" />
      <inertia
        ixx="6.7296E-05"
        ixy="5.9539E-12"
        ixz="3.2304E-12"
        iyy="6.7293E-05"
        iyz="2.4005E-13"
        izz="0.00011321" />
    </inertial>
    <visual>
      <origin
        xyz="0 0 0"
        rpy="0 0 0" />
      <geometry>
        <mesh
          filename="package://brum_description/meshes/right_wheel.STL" />
      </geometry>
      <material
        name="wheel_material">
        <color
          rgba="0.79216 0.81961 0.93333 1" />
      </material>
    </visual>
    <collision>
      <origin
        xyz="0 0 0"
        rpy="0 0 0" />
      <geometry>
        <mesh
          filename="package://brum_description/meshes/right_wheel.STL" />
      </geometry>
    </collision>
  </link>
  <joint
    name="right_wheel_joint"
    type="continuous">
    <origin
      xyz="0 -0.07925 -0.01815"
      rpy="1.5708 0 0" />
    <parent
      link="frame_link" />
    <child
      link="right_wheel" />
    <axis
      xyz="0 0 -1" />
  </joint>
  <link
    name="left_wheel">
    <inertial>
      <origin
        xyz="-1.8593E-08 -1.3155E-09 -0.011873"
        rpy="0 0 0" />
      <mass
        value="0.16695" />
      <inertia
        ixx="6.7296E-05"
        ixy="5.9539E-12"
        ixz="3.2303E-12"
        iyy="6.7293E-05"
        iyz="2.4005E-13"
        izz="0.00011321" />
    </inertial>
    <visual>
      <origin
        xyz="0 0 0"
        rpy="0 0 0" />
      <geometry>
        <mesh
          filename="package://brum_description/meshes/left_wheel.STL" />
      </geometry>
      <material
        name="wheel_material">
        <color
          rgba="0.79216 0.81961 0.93333 1" />
      </material>
    </visual>
    <collision>
      <origin
        xyz="0 0 0"
        rpy="0 0 0" />
      <geometry>
        <mesh
          filename="package://brum_description/meshes/left_wheel.STL" />
      </geometry>
    </collision>
  </link>
  <joint
    name="left_wheel_joint"
    type="continuous">
    <origin
      xyz="0 0.07925 -0.01815"
      rpy="-1.5708 0 0" />
    <parent
      link="frame_link" />
    <child
      link="left_wheel" />
    <axis
      xyz="0 0 1" />
  </joint>
  <link
    name="camera_mount_link">
    <inertial>
      <origin
        xyz="0.021441 -0.01339 -0.0052887"
        rpy="0 0 0" />
      <mass
        value="0.0099197" />
      <inertia
        ixx="9.6418E-07"
        ixy="3.9818E-07"
        ixz="1.3937E-07"
        iyy="2.1227E-06"
        iyz="-8.2985E-08"
        izz="2.9255E-06" />
    </inertial>
    <visual>
      <origin
        xyz="0 0 0"
        rpy="0 0 0" />
      <geometry>
        <mesh
          filename="package://brum_description/meshes/camera_mount_link.STL" />
      </geometry>
      <material
        name="">
        <color
          rgba="0.77647 0.75686 0.73725 1" />
      </material>
    </visual>
    <collision>
      <origin
        xyz="0 0 0"
        rpy="0 0 0" />
      <geometry>
        <mesh
          filename="package://brum_description/meshes/camera_mount_link.STL" />
      </geometry>
    </collision>
  </link>
  <joint
    name="camera_mount_joint"
    type="fixed">
    <origin
      xyz="0.0534488559945167 0.0262499999959915 0.0349999999999993"
      rpy="1.5707963267949 0 -1.5707963267949" />
    <parent
      link="frame_link" />
    <child
      link="camera_mount_link" />
    <axis
      xyz="0 0 0" />
  </joint>
  <link
    name="camera_link">
    <inertial>
      <origin
        xyz="-1.289E-12 -0.0056758 4.0787E-12"
        rpy="0 0 0" />
      <mass
        value="0.012179" />
      <inertia
        ixx="1.0523E-06"
        ixy="5.8674E-21"
        ixz="-9.7186E-13"
        iyy="2.1867E-06"
        iyz="-1.9335E-23"
        izz="1.4643E-06" />
    </inertial>
    <visual>
      <origin
        xyz="0 0 0"
        rpy="0 0 0" />
      <geometry>
        <mesh
          filename="package://brum_description/meshes/camera_link.STL" />
      </geometry>
      <material
        name="">
        <color
          rgba="0.10196 0.10196 0.10196 1" />
      </material>
    </visual>
    <collision>
      <origin
        xyz="0 0 0"
        rpy="0 0 0" />
      <geometry>
        <mesh
          filename="package://brum_description/meshes/camera_link.STL" />
      </geometry>
    </collision>
  </link>
  <joint
    name="camera_joint"
    type="fixed">
    <origin
      xyz="0.02625 -0.01777 -0.00875"
      rpy="1.5708 0 0" />
    <parent
      link="camera_mount_link" />
    <child
      link="camera_link" />
    <axis
      xyz="0 0 0" />
  </joint>
  <link
    name="under_cairrage_link">
    <inertial>
      <origin
        xyz="0.0375 0.0055345 -0.015987"
        rpy="0 0 0" />
      <mass
        value="0.014205" />
      <inertia
        ixx="1.8823E-06"
        ixy="-1.0574E-16"
        ixz="-5.3685E-16"
        iyy="8.7571E-06"
        iyz="-6.6875E-14"
        izz="7.595E-06" />
    </inertial>
    <visual>
      <origin
        xyz="0 0 0"
        rpy="0 0 0" />
      <geometry>
        <mesh
          filename="package://brum_description/meshes/under_cairrage_link.STL" />
      </geometry>
      <material
        name="">
        <color
          rgba="0.79216 0.81961 0.93333 1" />
      </material>
    </visual>
    <collision>
      <origin
        xyz="0 0 0"
        rpy="0 0 0" />
      <geometry>
        <mesh
          filename="package://brum_description/meshes/under_cairrage_link.STL" />
      </geometry>
    </collision>
  </link>
  <joint
    name="under_cairrage_joint"
    type="fixed">
    <origin
      xyz="0.0484 -0.0375 -0.02385"
      rpy="1.5708 0 1.5708" />
    <parent
      link="frame_link" />
    <child
      link="under_cairrage_link" />
    <axis
      xyz="0 0 0" />
  </joint>
  <link
    name="center_sonar_link">
    <inertial>
      <origin
        xyz="-0.00016398 -0.00016123 -0.0014079"
        rpy="0 0 0" />
      <mass
        value="0.0092238" />
      <inertia
        ixx="4.451E-07"
        ixy="5.3122E-10"
        ixz="9.1E-15"
        iyy="1.9394E-06"
        iyz="-3.5248E-09"
        izz="2.2647E-06" />
    </inertial>
    <visual>
      <origin
        xyz="0 0 0"
        rpy="0 0 0" />
      <geometry>
        <mesh
          filename="package://brum_description/meshes/center_sonar_link.STL" />
      </geometry>
      <material
        name="">
        <color
          rgba="0.79216 0.81961 0.93333 1" />
      </material>
    </visual>
    <collision>
      <origin
        xyz="0 0 0"
        rpy="0 0 0" />
      <geometry>
        <mesh
          filename="package://brum_description/meshes/center_sonar_link.STL" />
      </geometry>
    </collision>
  </link>
  <joint
    name="center_sonar_joint"
    type="fixed">
    <origin
      xyz="0.0377 0.0135 0.00675"
      rpy="0 0 0" />
    <parent
      link="under_cairrage_link" />
    <child
      link="center_sonar_link" />
    <axis
      xyz="0 0 0" />
  </joint>
  <link
    name="caster_link">
    <inertial>
      <origin
        xyz="9.9226E-16 0.0068784 -3.4694E-18"
        rpy="0 0 0" />
      <mass
        value="0.0062086" />
      <inertia
        ixx="3.5051E-07"
        ixy="9.6652E-23"
        ixz="4.0748E-16"
        iyy="5.7413E-07"
        iyz="-3.1987E-23"
        izz="6.0194E-07" />
    </inertial>
    <visual>
      <origin
        xyz="0 0 0"
        rpy="0 0 0" />
      <geometry>
        <mesh
          filename="package://brum_description/meshes/caster_link.STL" />
      </geometry>
      <material
        name="">
        <color
          rgba="1 1 1 1" />
      </material>
    </visual>
    <collision>
      <origin
        xyz="0 0 0"
        rpy="0 0 0" />
      <geometry>
        <mesh
          filename="package://brum_description/meshes/caster_link.STL" />
      </geometry>
    </collision>
  </link>
  <joint
    name="caster_joint"
    type="fixed">
    <origin
      xyz="-0.128 0 -0.032"
      rpy="-1.5708 0 -1.5708" />
    <parent
      link="frame_link" />
    <child
      link="caster_link" />
    <axis
      xyz="0 0 0" />
  </joint>
  <link
    name="laser_link">
    <inertial>
      <origin
        xyz="-0.0013136 0.020151 -0.00098529"
        rpy="0 0 0" />
      <mass
        value="0.061052" />
      <inertia
        ixx="1.129E-05"
        ixy="-8.7961E-08"
        ixz="-7.4689E-08"
        iyy="1.152E-05"
        iyz="3.4851E-07"
        izz="1.0065E-05" />
    </inertial>
    <visual>
      <origin
        xyz="0 0 0"
        rpy="0 0 0" />
      <geometry>
        <mesh
          filename="package://brum_description/meshes/laser_link.STL" />
      </geometry>
      <material
        name="">
        <color
          rgba="0.29804 0.29804 0.29804 1" />
      </material>
    </visual>
    <collision>
      <origin
        xyz="0 0 0"
        rpy="0 0 0" />
      <geometry>
        <mesh
          filename="package://brum_description/meshes/laser_link.STL" />
      </geometry>
    </collision>
  </link>
  <joint
    name="laser_joint"
    type="fixed">
    <origin
      xyz="0.017449 0 0.08845"
      rpy="-1.5708 0 -1.5708" />
    <parent
      link="frame_link" />
    <child
      link="laser_link" />
    <axis
      xyz="0 0 0" />
  </joint>
</robot>